<?xml version="1.0" encoding="utf-8"?>
<robot name="robot">

    <link name="base_link">
        <visual>
            <geometry>
                <box size="0.08 .2 .05" />
            </geometry>
            <origin rpy="0 0 1.54" xyz="0 0 0.02" />
            <material name="white">
                <color rgba="1 1 1 0.9" />
            </material>
        </visual>
        <collision>
            <geometry>
                <box size="0.09 .2 .05" />
            </geometry>
        </collision>
        <inertial>
            <mass value="10" />
            <inertia ixx="1.0" ixy="0.0" ixz="0.0" iyy="1.0" iyz="0.0" izz="1.0" />
        </inertial>
    </link>

    <link name="wheel_front_axle">
        <visual>
            <geometry>
                <cylinder length="0.11" radius="0.013" />
            </geometry>
            <origin rpy="1.6 1.6 0" xyz="0.07 0 0" />
            <material name="gray">
                <color rgba="0.8 0.8 0.9 1" />
            </material>
        </visual>
        <collision>
            <geometry>
                <cylinder length="0.11" radius="0.013" />
            </geometry>
        </collision>
        <inertial>
            <mass value="10" />
            <inertia ixx="1.0" ixy="0.0" ixz="0.0" iyy="1.0" iyz="0.0" izz="1.0" />
        </inertial>
    </link>
    <joint name="base_to_wheel_front_axle" type="fixed">
        <parent link="base_link" />
        <child link="wheel_front_axle" />
        <origin xyz="0 0 0" />
    </joint>

    <link name="wheel_back_axle">
        <visual>
            <geometry>
                <cylinder length="0.11" radius="0.013" />
            </geometry>
            <origin rpy="1.6 1.6 0" xyz="-0.07 0 0" />
            <material name="gray">
                <color rgba="0.8 0.8 0.9 1" />
            </material>
        </visual>
        <collision>
            <geometry>
                <cylinder length="0.11" radius="0.013" />
            </geometry>
        </collision>
        <inertial>
            <mass value="10" />
            <inertia ixx="1.0" ixy="0.0" ixz="0.0" iyy="1.0" iyz="0.0" izz="1.0" />
        </inertial>
    </link>
    <joint name="base_to_wheel_back_axle" type="fixed">
        <parent link="base_link" />
        <child link="wheel_back_axle" />
        <origin xyz="0 0 0" />
    </joint>
    <link name="wheel1_link">
        <inertial>
            <origin xyz="0 0.00856913 0" rpy="0 0 0" />
            <mass value="0.07503549" />
            <inertia ixx="0.00004285" ixy="0" ixz="0" iyy="0.00007349" iyz="0" izz="0.00004285" />
        </inertial>
        <visual>
            <origin xyz="0 0 0" rpy="0 0 0" />
            <geometry>
                <cylinder length="0.04" radius="0.04" />
            </geometry>
            <material name="">
                <color rgba="0 1 1 1" />
            </material>
        </visual>
        <collision>
            <origin xyz="0 0.0085707 0" rpy="0 0 0" />
            <geometry>
                <cylinder length="0.04" radius="0.04" />
            </geometry>
        </collision>
    </link>
    <joint name="wheel1_joint" type="continuous">
        <origin rpy="1.6 1.6 0" xyz="0.07 0.07 0" />
        <parent link="wheel_front_axle" />
        <child link="wheel1_link" />
        <axis xyz="0 0 1" />
    </joint>
    <link name="wheel2_link">
        <inertial>
            <origin xyz="0 0.00856913 0" rpy="0 0 0" />
            <mass value="0.07503549" />
            <inertia ixx="0.00004285" ixy="0" ixz="0" iyy="0.00007349" iyz="0" izz="0.00004285" />
        </inertial>
        <visual>
            <origin xyz="0 0 0" rpy="0 0 0" />
            <geometry>
                <cylinder length="0.04" radius="0.04" />
            </geometry>
            <material name="">
                <color rgba="0 1 1 1" />
            </material>
        </visual>
        <collision>
            <origin xyz="0 0 0" rpy="0 0 0" />
            <geometry>
                <cylinder length="0.04" radius="0.04" />
            </geometry>
        </collision>
    </link>
    <joint name="wheel2_joint" type="continuous">
        <origin rpy="1.6 1.6 0" xyz="-0.07 0.07 0" />
        <parent link="wheel_front_axle" />
        <child link="wheel2_link" />
        <axis xyz="0 0 1" />
    </joint>
    <link name="wheel3_link">
        <inertial>
            <origin xyz="0 0.00856913 0" rpy="0 0 0" />
            <mass value="0.07503549" />
            <inertia ixx="0.00004285" ixy="0" ixz="0" iyy="0.00007349" iyz="0" izz="0.00004285" />
        </inertial>
        <visual>
            <origin xyz="0 0 0" rpy="0 0 0" />
            <geometry>
                <cylinder length="0.04" radius="0.04" />
            </geometry>
            <material name="">
                <color rgba="0 1 1 1" />
            </material>
        </visual>
        <collision>
            <origin xyz="0 0 0" rpy="0 0 0" />
            <geometry>
                <cylinder length="0.04" radius="0.04" />
            </geometry>
        </collision>
    </link>
    <joint name="wheel3_joint" type="continuous">
        <origin rpy="1.6 1.6 0" xyz="0.07 -0.07 0" />
        <parent link="wheel_back_axle" />
        <child link="wheel3_link" />
        <axis xyz="0 0 1" />
    </joint>
    <link name="wheel4_link">
        <inertial>
            <origin xyz="0 0.00856913 0" rpy="0 0 0" />
            <mass value="0.07503549" />
            <inertia ixx="0.00004285" ixy="0" ixz="0" iyy="0.00007349" iyz="0" izz="0.00004285" />
        </inertial>
        <visual>
            <origin xyz="0 0 0" rpy="0 0 0" />
            <geometry>
                <cylinder length="0.04" radius="0.04" />
            </geometry>
            <material name="">
                <color rgba="0 1 1 1" />
            </material>
        </visual>
        <collision>
            <origin xyz="0 0 0" rpy="0 0 0" />
            <geometry>
                <cylinder length="0.04" radius="0.04" />
            </geometry>
        </collision>
    </link>
    <joint name="wheel4_joint" type="continuous">
        <origin rpy="1.6 1.6 0" xyz="-0.07 -0.07 0" />
        <parent link="wheel_back_axle" />
        <child link="wheel4_link" />
        <axis xyz="0 0 1" />
    </joint>


    <!-- 定义雷达的link -->
    <link name="lidar_link">
        <visual>
            <origin xyz="0 0 0.02" rpy="0 0 0" />
            <geometry>
                <cylinder length="0.03" radius="0.02" />
            </geometry>
            <material name="red">
                <color rgba="0.5 0.5 0.5 1.0" />
            </material>
        </visual>
        <collision>
            <origin xyz="0 0 0.02" rpy="0 0 0" />
            <geometry>
                <cylinder length="0.03" radius="0.02" />
            </geometry>
        </collision>
    </link>

    <!-- 定义雷达的joint -->
    <joint name="lidar_joint" type="fixed">
        <origin xyz="0 0 0.02" rpy="0 0 0" />
        <parent link="base_link" />
        <child link="lidar_link" />
    </joint>

    <!-- 添加雷达传感器插件 -->
    <gazebo>
        <sensor type="ray" name="lidar_sensor">
            <pose>0 0 0 0 0 0</pose>
            <visualize>true</visualize>
            <update_rate>30</update_rate>
            <ray>
                <scan>
                    <horizontal>
                        <samples>640</samples>
                        <resolution>1</resolution>
                        <min_angle>-1.5708</min_angle>
                        <max_angle>1.5708</max_angle>
                    </horizontal>
                </scan>
                <range>
                    <min>0.1</min>
                    <max>30.0</max>
                    <resolution>0.01</resolution>
                </range>
            </ray>
            <plugin name="gazebo_ros_laser_controller" filename="libgazebo_ros_laser.so">
                <topicName>/scan</topicName>
                <frameName>lidar_link</frameName>
            </plugin>
        </sensor>
    </gazebo>

</robot>